[2023-10-04 18:09:12,833] ERROR Internal Server Error: /news/1/edit/ C:\Users\User\AppData\Local\Programs\Python\Python311\Lib\site-packages\django\utils\log.py
(<class 'django.core.exceptions.ImproperlyConfigured'>, ImproperlyConfigured('No URL to redirect to.  Either provide a url or define a get_absolute_url method on the Model.'), <traceback object at 0x000001B613F5A6C0>)
Traceback (most recent call last):
  File "C:\Users\User\AppData\Local\Programs\Python\Python311\Lib\site-packages\django\views\generic\edit.py", line 125, in get_success_url
    url = self.object.get_absolute_url()
          ^^^^^^^^^^^^^^^^^^^^^^^^^^^^
AttributeError: 'Post' object has no attribute 'get_absolute_url'

During handling of the above exception, another exception occurred:

Traceback (most recent call last):
  File "C:\Users\User\AppData\Local\Programs\Python\Python311\Lib\site-packages\django\core\handlers\exception.py", line 55, in inner
    response = get_response(request)
               ^^^^^^^^^^^^^^^^^^^^^
  File "C:\Users\User\AppData\Local\Programs\Python\Python311\Lib\site-packages\django\core\handlers\base.py", line 197, in _get_response
    response = wrapped_callback(request, *callback_args, **callback_kwargs)
               ^^^^^^^^^^^^^^^^^^^^^^^^^^^^^^^^^^^^^^^^^^^^^^^^^^^^^^^^^^^^
  File "C:\Users\User\AppData\Local\Programs\Python\Python311\Lib\site-packages\django\views\generic\base.py", line 104, in view
    return self.dispatch(request, *args, **kwargs)
           ^^^^^^^^^^^^^^^^^^^^^^^^^^^^^^^^^^^^^^^
  File "C:\Users\User\AppData\Local\Programs\Python\Python311\Lib\site-packages\django\contrib\auth\mixins.py", line 73, in dispatch
    return super().dispatch(request, *args, **kwargs)
           ^^^^^^^^^^^^^^^^^^^^^^^^^^^^^^^^^^^^^^^^^^
  File "C:\Users\User\AppData\Local\Programs\Python\Python311\Lib\site-packages\django\contrib\auth\mixins.py", line 109, in dispatch
    return super().dispatch(request, *args, **kwargs)
           ^^^^^^^^^^^^^^^^^^^^^^^^^^^^^^^^^^^^^^^^^^
  File "C:\Users\User\AppData\Local\Programs\Python\Python311\Lib\site-packages\django\views\generic\base.py", line 143, in dispatch
    return handler(request, *args, **kwargs)
           ^^^^^^^^^^^^^^^^^^^^^^^^^^^^^^^^^
  File "C:\Users\User\AppData\Local\Programs\Python\Python311\Lib\site-packages\django\views\generic\edit.py", line 208, in post
    return super().post(request, *args, **kwargs)
           ^^^^^^^^^^^^^^^^^^^^^^^^^^^^^^^^^^^^^^
  File "C:\Users\User\AppData\Local\Programs\Python\Python311\Lib\site-packages\django\views\generic\edit.py", line 153, in post
    return self.form_valid(form)
           ^^^^^^^^^^^^^^^^^^^^^
  File "C:\Users\User\AppData\Local\Programs\Python\Python311\Lib\site-packages\django\views\generic\edit.py", line 136, in form_valid
    return super().form_valid(form)
           ^^^^^^^^^^^^^^^^^^^^^^^^
  File "C:\Users\User\AppData\Local\Programs\Python\Python311\Lib\site-packages\django\views\generic\edit.py", line 65, in form_valid
    return HttpResponseRedirect(self.get_success_url())
                                ^^^^^^^^^^^^^^^^^^^^^^
  File "C:\Users\User\AppData\Local\Programs\Python\Python311\Lib\site-packages\django\views\generic\edit.py", line 127, in get_success_url
    raise ImproperlyConfigured(
django.core.exceptions.ImproperlyConfigured: No URL to redirect to.  Either provide a url or define a get_absolute_url method on the Model.
[2023-10-04 18:09:12,917] ERROR "POST /news/1/edit/ HTTP/1.1" 500 113324 C:\Users\User\AppData\Local\Programs\Python\Python311\Lib\site-packages\django\core\servers\basehttp.py
None
[2023-10-04 18:09:18,176] ERROR Internal Server Error: /news/1/edit/ C:\Users\User\AppData\Local\Programs\Python\Python311\Lib\site-packages\django\utils\log.py
(<class 'django.core.exceptions.ImproperlyConfigured'>, ImproperlyConfigured('No URL to redirect to.  Either provide a url or define a get_absolute_url method on the Model.'), <traceback object at 0x000001B613F84840>)
Traceback (most recent call last):
  File "C:\Users\User\AppData\Local\Programs\Python\Python311\Lib\site-packages\django\views\generic\edit.py", line 125, in get_success_url
    url = self.object.get_absolute_url()
          ^^^^^^^^^^^^^^^^^^^^^^^^^^^^
AttributeError: 'Post' object has no attribute 'get_absolute_url'

During handling of the above exception, another exception occurred:

Traceback (most recent call last):
  File "C:\Users\User\AppData\Local\Programs\Python\Python311\Lib\site-packages\django\core\handlers\exception.py", line 55, in inner
    response = get_response(request)
               ^^^^^^^^^^^^^^^^^^^^^
  File "C:\Users\User\AppData\Local\Programs\Python\Python311\Lib\site-packages\django\core\handlers\base.py", line 197, in _get_response
    response = wrapped_callback(request, *callback_args, **callback_kwargs)
               ^^^^^^^^^^^^^^^^^^^^^^^^^^^^^^^^^^^^^^^^^^^^^^^^^^^^^^^^^^^^
  File "C:\Users\User\AppData\Local\Programs\Python\Python311\Lib\site-packages\django\views\generic\base.py", line 104, in view
    return self.dispatch(request, *args, **kwargs)
           ^^^^^^^^^^^^^^^^^^^^^^^^^^^^^^^^^^^^^^^
  File "C:\Users\User\AppData\Local\Programs\Python\Python311\Lib\site-packages\django\contrib\auth\mixins.py", line 73, in dispatch
    return super().dispatch(request, *args, **kwargs)
           ^^^^^^^^^^^^^^^^^^^^^^^^^^^^^^^^^^^^^^^^^^
  File "C:\Users\User\AppData\Local\Programs\Python\Python311\Lib\site-packages\django\contrib\auth\mixins.py", line 109, in dispatch
    return super().dispatch(request, *args, **kwargs)
           ^^^^^^^^^^^^^^^^^^^^^^^^^^^^^^^^^^^^^^^^^^
  File "C:\Users\User\AppData\Local\Programs\Python\Python311\Lib\site-packages\django\views\generic\base.py", line 143, in dispatch
    return handler(request, *args, **kwargs)
           ^^^^^^^^^^^^^^^^^^^^^^^^^^^^^^^^^
  File "C:\Users\User\AppData\Local\Programs\Python\Python311\Lib\site-packages\django\views\generic\edit.py", line 208, in post
    return super().post(request, *args, **kwargs)
           ^^^^^^^^^^^^^^^^^^^^^^^^^^^^^^^^^^^^^^
  File "C:\Users\User\AppData\Local\Programs\Python\Python311\Lib\site-packages\django\views\generic\edit.py", line 153, in post
    return self.form_valid(form)
           ^^^^^^^^^^^^^^^^^^^^^
  File "C:\Users\User\AppData\Local\Programs\Python\Python311\Lib\site-packages\django\views\generic\edit.py", line 136, in form_valid
    return super().form_valid(form)
           ^^^^^^^^^^^^^^^^^^^^^^^^
  File "C:\Users\User\AppData\Local\Programs\Python\Python311\Lib\site-packages\django\views\generic\edit.py", line 65, in form_valid
    return HttpResponseRedirect(self.get_success_url())
                                ^^^^^^^^^^^^^^^^^^^^^^
  File "C:\Users\User\AppData\Local\Programs\Python\Python311\Lib\site-packages\django\views\generic\edit.py", line 127, in get_success_url
    raise ImproperlyConfigured(
django.core.exceptions.ImproperlyConfigured: No URL to redirect to.  Either provide a url or define a get_absolute_url method on the Model.
[2023-10-04 18:09:18,320] ERROR "POST /news/1/edit/ HTTP/1.1" 500 113324 C:\Users\User\AppData\Local\Programs\Python\Python311\Lib\site-packages\django\core\servers\basehttp.py
None
[2023-10-04 19:37:42,632] ERROR Internal Server Error: /news/1/edit/ C:\Users\User\AppData\Local\Programs\Python\Python311\Lib\site-packages\django\utils\log.py
(<class 'django.core.exceptions.ImproperlyConfigured'>, ImproperlyConfigured('No URL to redirect to.  Either provide a url or define a get_absolute_url method on the Model.'), <traceback object at 0x000002D6B7374680>)
Traceback (most recent call last):
  File "C:\Users\User\AppData\Local\Programs\Python\Python311\Lib\site-packages\django\views\generic\edit.py", line 125, in get_success_url
    url = self.object.get_absolute_url()
          ^^^^^^^^^^^^^^^^^^^^^^^^^^^^
AttributeError: 'Post' object has no attribute 'get_absolute_url'

During handling of the above exception, another exception occurred:

Traceback (most recent call last):
  File "C:\Users\User\AppData\Local\Programs\Python\Python311\Lib\site-packages\django\core\handlers\exception.py", line 55, in inner
    response = get_response(request)
               ^^^^^^^^^^^^^^^^^^^^^
  File "C:\Users\User\AppData\Local\Programs\Python\Python311\Lib\site-packages\django\core\handlers\base.py", line 197, in _get_response
    response = wrapped_callback(request, *callback_args, **callback_kwargs)
               ^^^^^^^^^^^^^^^^^^^^^^^^^^^^^^^^^^^^^^^^^^^^^^^^^^^^^^^^^^^^
  File "C:\Users\User\AppData\Local\Programs\Python\Python311\Lib\site-packages\django\views\generic\base.py", line 104, in view
    return self.dispatch(request, *args, **kwargs)
           ^^^^^^^^^^^^^^^^^^^^^^^^^^^^^^^^^^^^^^^
  File "C:\Users\User\AppData\Local\Programs\Python\Python311\Lib\site-packages\django\contrib\auth\mixins.py", line 73, in dispatch
    return super().dispatch(request, *args, **kwargs)
           ^^^^^^^^^^^^^^^^^^^^^^^^^^^^^^^^^^^^^^^^^^
  File "C:\Users\User\AppData\Local\Programs\Python\Python311\Lib\site-packages\django\contrib\auth\mixins.py", line 109, in dispatch
    return super().dispatch(request, *args, **kwargs)
           ^^^^^^^^^^^^^^^^^^^^^^^^^^^^^^^^^^^^^^^^^^
  File "C:\Users\User\AppData\Local\Programs\Python\Python311\Lib\site-packages\django\views\generic\base.py", line 143, in dispatch
    return handler(request, *args, **kwargs)
           ^^^^^^^^^^^^^^^^^^^^^^^^^^^^^^^^^
  File "C:\Users\User\AppData\Local\Programs\Python\Python311\Lib\site-packages\django\views\generic\edit.py", line 208, in post
    return super().post(request, *args, **kwargs)
           ^^^^^^^^^^^^^^^^^^^^^^^^^^^^^^^^^^^^^^
  File "C:\Users\User\AppData\Local\Programs\Python\Python311\Lib\site-packages\django\views\generic\edit.py", line 153, in post
    return self.form_valid(form)
           ^^^^^^^^^^^^^^^^^^^^^
  File "C:\Users\User\AppData\Local\Programs\Python\Python311\Lib\site-packages\django\views\generic\edit.py", line 136, in form_valid
    return super().form_valid(form)
           ^^^^^^^^^^^^^^^^^^^^^^^^
  File "C:\Users\User\AppData\Local\Programs\Python\Python311\Lib\site-packages\django\views\generic\edit.py", line 65, in form_valid
    return HttpResponseRedirect(self.get_success_url())
                                ^^^^^^^^^^^^^^^^^^^^^^
  File "C:\Users\User\AppData\Local\Programs\Python\Python311\Lib\site-packages\django\views\generic\edit.py", line 127, in get_success_url
    raise ImproperlyConfigured(
django.core.exceptions.ImproperlyConfigured: No URL to redirect to.  Either provide a url or define a get_absolute_url method on the Model.
[2023-10-04 19:37:42,666] ERROR "POST /news/1/edit/ HTTP/1.1" 500 113433 C:\Users\User\AppData\Local\Programs\Python\Python311\Lib\site-packages\django\core\servers\basehttp.py
None
[2023-10-04 19:37:49,583] ERROR Internal Server Error: /news/1/edit/ C:\Users\User\AppData\Local\Programs\Python\Python311\Lib\site-packages\django\utils\log.py
(<class 'django.core.exceptions.ImproperlyConfigured'>, ImproperlyConfigured('No URL to redirect to.  Either provide a url or define a get_absolute_url method on the Model.'), <traceback object at 0x000002D6B743A240>)
Traceback (most recent call last):
  File "C:\Users\User\AppData\Local\Programs\Python\Python311\Lib\site-packages\django\views\generic\edit.py", line 125, in get_success_url
    url = self.object.get_absolute_url()
          ^^^^^^^^^^^^^^^^^^^^^^^^^^^^
AttributeError: 'Post' object has no attribute 'get_absolute_url'

During handling of the above exception, another exception occurred:

Traceback (most recent call last):
  File "C:\Users\User\AppData\Local\Programs\Python\Python311\Lib\site-packages\django\core\handlers\exception.py", line 55, in inner
    response = get_response(request)
               ^^^^^^^^^^^^^^^^^^^^^
  File "C:\Users\User\AppData\Local\Programs\Python\Python311\Lib\site-packages\django\core\handlers\base.py", line 197, in _get_response
    response = wrapped_callback(request, *callback_args, **callback_kwargs)
               ^^^^^^^^^^^^^^^^^^^^^^^^^^^^^^^^^^^^^^^^^^^^^^^^^^^^^^^^^^^^
  File "C:\Users\User\AppData\Local\Programs\Python\Python311\Lib\site-packages\django\views\generic\base.py", line 104, in view
    return self.dispatch(request, *args, **kwargs)
           ^^^^^^^^^^^^^^^^^^^^^^^^^^^^^^^^^^^^^^^
  File "C:\Users\User\AppData\Local\Programs\Python\Python311\Lib\site-packages\django\contrib\auth\mixins.py", line 73, in dispatch
    return super().dispatch(request, *args, **kwargs)
           ^^^^^^^^^^^^^^^^^^^^^^^^^^^^^^^^^^^^^^^^^^
  File "C:\Users\User\AppData\Local\Programs\Python\Python311\Lib\site-packages\django\contrib\auth\mixins.py", line 109, in dispatch
    return super().dispatch(request, *args, **kwargs)
           ^^^^^^^^^^^^^^^^^^^^^^^^^^^^^^^^^^^^^^^^^^
  File "C:\Users\User\AppData\Local\Programs\Python\Python311\Lib\site-packages\django\views\generic\base.py", line 143, in dispatch
    return handler(request, *args, **kwargs)
           ^^^^^^^^^^^^^^^^^^^^^^^^^^^^^^^^^
  File "C:\Users\User\AppData\Local\Programs\Python\Python311\Lib\site-packages\django\views\generic\edit.py", line 208, in post
    return super().post(request, *args, **kwargs)
           ^^^^^^^^^^^^^^^^^^^^^^^^^^^^^^^^^^^^^^
  File "C:\Users\User\AppData\Local\Programs\Python\Python311\Lib\site-packages\django\views\generic\edit.py", line 153, in post
    return self.form_valid(form)
           ^^^^^^^^^^^^^^^^^^^^^
  File "C:\Users\User\AppData\Local\Programs\Python\Python311\Lib\site-packages\django\views\generic\edit.py", line 136, in form_valid
    return super().form_valid(form)
           ^^^^^^^^^^^^^^^^^^^^^^^^
  File "C:\Users\User\AppData\Local\Programs\Python\Python311\Lib\site-packages\django\views\generic\edit.py", line 65, in form_valid
    return HttpResponseRedirect(self.get_success_url())
                                ^^^^^^^^^^^^^^^^^^^^^^
  File "C:\Users\User\AppData\Local\Programs\Python\Python311\Lib\site-packages\django\views\generic\edit.py", line 127, in get_success_url
    raise ImproperlyConfigured(
django.core.exceptions.ImproperlyConfigured: No URL to redirect to.  Either provide a url or define a get_absolute_url method on the Model.
[2023-10-04 19:37:49,697] ERROR "POST /news/1/edit/ HTTP/1.1" 500 113433 C:\Users\User\AppData\Local\Programs\Python\Python311\Lib\site-packages\django\core\servers\basehttp.py
None
[2023-10-04 19:39:50,368] ERROR Internal Server Error: /news/2/edit/ C:\Users\User\AppData\Local\Programs\Python\Python311\Lib\site-packages\django\utils\log.py
(<class 'django.core.exceptions.ImproperlyConfigured'>, ImproperlyConfigured('No URL to redirect to.  Either provide a url or define a get_absolute_url method on the Model.'), <traceback object at 0x000001B880AE99C0>)
Traceback (most recent call last):
  File "C:\Users\User\AppData\Local\Programs\Python\Python311\Lib\site-packages\django\views\generic\edit.py", line 125, in get_success_url
    url = self.object.get_absolute_url()
          ^^^^^^^^^^^^^^^^^^^^^^^^^^^^
AttributeError: 'Post' object has no attribute 'get_absolute_url'

During handling of the above exception, another exception occurred:

Traceback (most recent call last):
  File "C:\Users\User\AppData\Local\Programs\Python\Python311\Lib\site-packages\django\core\handlers\exception.py", line 55, in inner
    response = get_response(request)
               ^^^^^^^^^^^^^^^^^^^^^
  File "C:\Users\User\AppData\Local\Programs\Python\Python311\Lib\site-packages\django\core\handlers\base.py", line 197, in _get_response
    response = wrapped_callback(request, *callback_args, **callback_kwargs)
               ^^^^^^^^^^^^^^^^^^^^^^^^^^^^^^^^^^^^^^^^^^^^^^^^^^^^^^^^^^^^
  File "C:\Users\User\AppData\Local\Programs\Python\Python311\Lib\site-packages\django\views\generic\base.py", line 104, in view
    return self.dispatch(request, *args, **kwargs)
           ^^^^^^^^^^^^^^^^^^^^^^^^^^^^^^^^^^^^^^^
  File "C:\Users\User\AppData\Local\Programs\Python\Python311\Lib\site-packages\django\contrib\auth\mixins.py", line 73, in dispatch
    return super().dispatch(request, *args, **kwargs)
           ^^^^^^^^^^^^^^^^^^^^^^^^^^^^^^^^^^^^^^^^^^
  File "C:\Users\User\AppData\Local\Programs\Python\Python311\Lib\site-packages\django\contrib\auth\mixins.py", line 109, in dispatch
    return super().dispatch(request, *args, **kwargs)
           ^^^^^^^^^^^^^^^^^^^^^^^^^^^^^^^^^^^^^^^^^^
  File "C:\Users\User\AppData\Local\Programs\Python\Python311\Lib\site-packages\django\views\generic\base.py", line 143, in dispatch
    return handler(request, *args, **kwargs)
           ^^^^^^^^^^^^^^^^^^^^^^^^^^^^^^^^^
  File "C:\Users\User\AppData\Local\Programs\Python\Python311\Lib\site-packages\django\views\generic\edit.py", line 208, in post
    return super().post(request, *args, **kwargs)
           ^^^^^^^^^^^^^^^^^^^^^^^^^^^^^^^^^^^^^^
  File "C:\Users\User\AppData\Local\Programs\Python\Python311\Lib\site-packages\django\views\generic\edit.py", line 153, in post
    return self.form_valid(form)
           ^^^^^^^^^^^^^^^^^^^^^
  File "C:\Users\User\AppData\Local\Programs\Python\Python311\Lib\site-packages\django\views\generic\edit.py", line 136, in form_valid
    return super().form_valid(form)
           ^^^^^^^^^^^^^^^^^^^^^^^^
  File "C:\Users\User\AppData\Local\Programs\Python\Python311\Lib\site-packages\django\views\generic\edit.py", line 65, in form_valid
    return HttpResponseRedirect(self.get_success_url())
                                ^^^^^^^^^^^^^^^^^^^^^^
  File "C:\Users\User\AppData\Local\Programs\Python\Python311\Lib\site-packages\django\views\generic\edit.py", line 127, in get_success_url
    raise ImproperlyConfigured(
django.core.exceptions.ImproperlyConfigured: No URL to redirect to.  Either provide a url or define a get_absolute_url method on the Model.
[2023-10-04 19:39:50,404] ERROR "POST /news/2/edit/ HTTP/1.1" 500 113246 C:\Users\User\AppData\Local\Programs\Python\Python311\Lib\site-packages\django\core\servers\basehttp.py
None
[2023-10-04 19:40:36,300] ERROR Internal Server Error: /news/3/edit/ C:\Users\User\AppData\Local\Programs\Python\Python311\Lib\site-packages\django\utils\log.py
(<class 'django.core.exceptions.ImproperlyConfigured'>, ImproperlyConfigured('No URL to redirect to.  Either provide a url or define a get_absolute_url method on the Model.'), <traceback object at 0x000001B880A015C0>)
Traceback (most recent call last):
  File "C:\Users\User\AppData\Local\Programs\Python\Python311\Lib\site-packages\django\views\generic\edit.py", line 125, in get_success_url
    url = self.object.get_absolute_url()
          ^^^^^^^^^^^^^^^^^^^^^^^^^^^^
AttributeError: 'Post' object has no attribute 'get_absolute_url'

During handling of the above exception, another exception occurred:

Traceback (most recent call last):
  File "C:\Users\User\AppData\Local\Programs\Python\Python311\Lib\site-packages\django\core\handlers\exception.py", line 55, in inner
    response = get_response(request)
               ^^^^^^^^^^^^^^^^^^^^^
  File "C:\Users\User\AppData\Local\Programs\Python\Python311\Lib\site-packages\django\core\handlers\base.py", line 197, in _get_response
    response = wrapped_callback(request, *callback_args, **callback_kwargs)
               ^^^^^^^^^^^^^^^^^^^^^^^^^^^^^^^^^^^^^^^^^^^^^^^^^^^^^^^^^^^^
  File "C:\Users\User\AppData\Local\Programs\Python\Python311\Lib\site-packages\django\views\generic\base.py", line 104, in view
    return self.dispatch(request, *args, **kwargs)
           ^^^^^^^^^^^^^^^^^^^^^^^^^^^^^^^^^^^^^^^
  File "C:\Users\User\AppData\Local\Programs\Python\Python311\Lib\site-packages\django\contrib\auth\mixins.py", line 73, in dispatch
    return super().dispatch(request, *args, **kwargs)
           ^^^^^^^^^^^^^^^^^^^^^^^^^^^^^^^^^^^^^^^^^^
  File "C:\Users\User\AppData\Local\Programs\Python\Python311\Lib\site-packages\django\contrib\auth\mixins.py", line 109, in dispatch
    return super().dispatch(request, *args, **kwargs)
           ^^^^^^^^^^^^^^^^^^^^^^^^^^^^^^^^^^^^^^^^^^
  File "C:\Users\User\AppData\Local\Programs\Python\Python311\Lib\site-packages\django\views\generic\base.py", line 143, in dispatch
    return handler(request, *args, **kwargs)
           ^^^^^^^^^^^^^^^^^^^^^^^^^^^^^^^^^
  File "C:\Users\User\AppData\Local\Programs\Python\Python311\Lib\site-packages\django\views\generic\edit.py", line 208, in post
    return super().post(request, *args, **kwargs)
           ^^^^^^^^^^^^^^^^^^^^^^^^^^^^^^^^^^^^^^
  File "C:\Users\User\AppData\Local\Programs\Python\Python311\Lib\site-packages\django\views\generic\edit.py", line 153, in post
    return self.form_valid(form)
           ^^^^^^^^^^^^^^^^^^^^^
  File "C:\Users\User\AppData\Local\Programs\Python\Python311\Lib\site-packages\django\views\generic\edit.py", line 136, in form_valid
    return super().form_valid(form)
           ^^^^^^^^^^^^^^^^^^^^^^^^
  File "C:\Users\User\AppData\Local\Programs\Python\Python311\Lib\site-packages\django\views\generic\edit.py", line 65, in form_valid
    return HttpResponseRedirect(self.get_success_url())
                                ^^^^^^^^^^^^^^^^^^^^^^
  File "C:\Users\User\AppData\Local\Programs\Python\Python311\Lib\site-packages\django\views\generic\edit.py", line 127, in get_success_url
    raise ImproperlyConfigured(
django.core.exceptions.ImproperlyConfigured: No URL to redirect to.  Either provide a url or define a get_absolute_url method on the Model.
[2023-10-04 19:40:36,389] ERROR "POST /news/3/edit/ HTTP/1.1" 500 113274 C:\Users\User\AppData\Local\Programs\Python\Python311\Lib\site-packages\django\core\servers\basehttp.py
None
[2023-10-04 19:41:32,794] ERROR Internal Server Error: /news/5/edit/ C:\Users\User\AppData\Local\Programs\Python\Python311\Lib\site-packages\django\utils\log.py
(<class 'django.core.exceptions.ImproperlyConfigured'>, ImproperlyConfigured('No URL to redirect to.  Either provide a url or define a get_absolute_url method on the Model.'), <traceback object at 0x000001B880B81940>)
Traceback (most recent call last):
  File "C:\Users\User\AppData\Local\Programs\Python\Python311\Lib\site-packages\django\views\generic\edit.py", line 125, in get_success_url
    url = self.object.get_absolute_url()
          ^^^^^^^^^^^^^^^^^^^^^^^^^^^^
AttributeError: 'Post' object has no attribute 'get_absolute_url'

During handling of the above exception, another exception occurred:

Traceback (most recent call last):
  File "C:\Users\User\AppData\Local\Programs\Python\Python311\Lib\site-packages\django\core\handlers\exception.py", line 55, in inner
    response = get_response(request)
               ^^^^^^^^^^^^^^^^^^^^^
  File "C:\Users\User\AppData\Local\Programs\Python\Python311\Lib\site-packages\django\core\handlers\base.py", line 197, in _get_response
    response = wrapped_callback(request, *callback_args, **callback_kwargs)
               ^^^^^^^^^^^^^^^^^^^^^^^^^^^^^^^^^^^^^^^^^^^^^^^^^^^^^^^^^^^^
  File "C:\Users\User\AppData\Local\Programs\Python\Python311\Lib\site-packages\django\views\generic\base.py", line 104, in view
    return self.dispatch(request, *args, **kwargs)
           ^^^^^^^^^^^^^^^^^^^^^^^^^^^^^^^^^^^^^^^
  File "C:\Users\User\AppData\Local\Programs\Python\Python311\Lib\site-packages\django\contrib\auth\mixins.py", line 73, in dispatch
    return super().dispatch(request, *args, **kwargs)
           ^^^^^^^^^^^^^^^^^^^^^^^^^^^^^^^^^^^^^^^^^^
  File "C:\Users\User\AppData\Local\Programs\Python\Python311\Lib\site-packages\django\contrib\auth\mixins.py", line 109, in dispatch
    return super().dispatch(request, *args, **kwargs)
           ^^^^^^^^^^^^^^^^^^^^^^^^^^^^^^^^^^^^^^^^^^
  File "C:\Users\User\AppData\Local\Programs\Python\Python311\Lib\site-packages\django\views\generic\base.py", line 143, in dispatch
    return handler(request, *args, **kwargs)
           ^^^^^^^^^^^^^^^^^^^^^^^^^^^^^^^^^
  File "C:\Users\User\AppData\Local\Programs\Python\Python311\Lib\site-packages\django\views\generic\edit.py", line 208, in post
    return super().post(request, *args, **kwargs)
           ^^^^^^^^^^^^^^^^^^^^^^^^^^^^^^^^^^^^^^
  File "C:\Users\User\AppData\Local\Programs\Python\Python311\Lib\site-packages\django\views\generic\edit.py", line 153, in post
    return self.form_valid(form)
           ^^^^^^^^^^^^^^^^^^^^^
  File "C:\Users\User\AppData\Local\Programs\Python\Python311\Lib\site-packages\django\views\generic\edit.py", line 136, in form_valid
    return super().form_valid(form)
           ^^^^^^^^^^^^^^^^^^^^^^^^
  File "C:\Users\User\AppData\Local\Programs\Python\Python311\Lib\site-packages\django\views\generic\edit.py", line 65, in form_valid
    return HttpResponseRedirect(self.get_success_url())
                                ^^^^^^^^^^^^^^^^^^^^^^
  File "C:\Users\User\AppData\Local\Programs\Python\Python311\Lib\site-packages\django\views\generic\edit.py", line 127, in get_success_url
    raise ImproperlyConfigured(
django.core.exceptions.ImproperlyConfigured: No URL to redirect to.  Either provide a url or define a get_absolute_url method on the Model.
[2023-10-04 19:41:32,824] ERROR "POST /news/5/edit/ HTTP/1.1" 500 113300 C:\Users\User\AppData\Local\Programs\Python\Python311\Lib\site-packages\django\core\servers\basehttp.py
None
[2023-10-04 19:41:57,166] ERROR Internal Server Error: /news/6/edit/ C:\Users\User\AppData\Local\Programs\Python\Python311\Lib\site-packages\django\utils\log.py
(<class 'django.core.exceptions.ImproperlyConfigured'>, ImproperlyConfigured('No URL to redirect to.  Either provide a url or define a get_absolute_url method on the Model.'), <traceback object at 0x000001B880A01840>)
Traceback (most recent call last):
  File "C:\Users\User\AppData\Local\Programs\Python\Python311\Lib\site-packages\django\views\generic\edit.py", line 125, in get_success_url
    url = self.object.get_absolute_url()
          ^^^^^^^^^^^^^^^^^^^^^^^^^^^^
AttributeError: 'Post' object has no attribute 'get_absolute_url'

During handling of the above exception, another exception occurred:

Traceback (most recent call last):
  File "C:\Users\User\AppData\Local\Programs\Python\Python311\Lib\site-packages\django\core\handlers\exception.py", line 55, in inner
    response = get_response(request)
               ^^^^^^^^^^^^^^^^^^^^^
  File "C:\Users\User\AppData\Local\Programs\Python\Python311\Lib\site-packages\django\core\handlers\base.py", line 197, in _get_response
    response = wrapped_callback(request, *callback_args, **callback_kwargs)
               ^^^^^^^^^^^^^^^^^^^^^^^^^^^^^^^^^^^^^^^^^^^^^^^^^^^^^^^^^^^^
  File "C:\Users\User\AppData\Local\Programs\Python\Python311\Lib\site-packages\django\views\generic\base.py", line 104, in view
    return self.dispatch(request, *args, **kwargs)
           ^^^^^^^^^^^^^^^^^^^^^^^^^^^^^^^^^^^^^^^
  File "C:\Users\User\AppData\Local\Programs\Python\Python311\Lib\site-packages\django\contrib\auth\mixins.py", line 73, in dispatch
    return super().dispatch(request, *args, **kwargs)
           ^^^^^^^^^^^^^^^^^^^^^^^^^^^^^^^^^^^^^^^^^^
  File "C:\Users\User\AppData\Local\Programs\Python\Python311\Lib\site-packages\django\contrib\auth\mixins.py", line 109, in dispatch
    return super().dispatch(request, *args, **kwargs)
           ^^^^^^^^^^^^^^^^^^^^^^^^^^^^^^^^^^^^^^^^^^
  File "C:\Users\User\AppData\Local\Programs\Python\Python311\Lib\site-packages\django\views\generic\base.py", line 143, in dispatch
    return handler(request, *args, **kwargs)
           ^^^^^^^^^^^^^^^^^^^^^^^^^^^^^^^^^
  File "C:\Users\User\AppData\Local\Programs\Python\Python311\Lib\site-packages\django\views\generic\edit.py", line 208, in post
    return super().post(request, *args, **kwargs)
           ^^^^^^^^^^^^^^^^^^^^^^^^^^^^^^^^^^^^^^
  File "C:\Users\User\AppData\Local\Programs\Python\Python311\Lib\site-packages\django\views\generic\edit.py", line 153, in post
    return self.form_valid(form)
           ^^^^^^^^^^^^^^^^^^^^^
  File "C:\Users\User\AppData\Local\Programs\Python\Python311\Lib\site-packages\django\views\generic\edit.py", line 136, in form_valid
    return super().form_valid(form)
           ^^^^^^^^^^^^^^^^^^^^^^^^
  File "C:\Users\User\AppData\Local\Programs\Python\Python311\Lib\site-packages\django\views\generic\edit.py", line 65, in form_valid
    return HttpResponseRedirect(self.get_success_url())
                                ^^^^^^^^^^^^^^^^^^^^^^
  File "C:\Users\User\AppData\Local\Programs\Python\Python311\Lib\site-packages\django\views\generic\edit.py", line 127, in get_success_url
    raise ImproperlyConfigured(
django.core.exceptions.ImproperlyConfigured: No URL to redirect to.  Either provide a url or define a get_absolute_url method on the Model.
[2023-10-04 19:41:57,197] ERROR "POST /news/6/edit/ HTTP/1.1" 500 113288 C:\Users\User\AppData\Local\Programs\Python\Python311\Lib\site-packages\django\core\servers\basehttp.py
None
[2023-10-04 19:42:45,406] ERROR Internal Server Error: /news/11/edit/ C:\Users\User\AppData\Local\Programs\Python\Python311\Lib\site-packages\django\utils\log.py
(<class 'django.core.exceptions.ImproperlyConfigured'>, ImproperlyConfigured('No URL to redirect to.  Either provide a url or define a get_absolute_url method on the Model.'), <traceback object at 0x000001B880AEBA80>)
Traceback (most recent call last):
  File "C:\Users\User\AppData\Local\Programs\Python\Python311\Lib\site-packages\django\views\generic\edit.py", line 125, in get_success_url
    url = self.object.get_absolute_url()
          ^^^^^^^^^^^^^^^^^^^^^^^^^^^^
AttributeError: 'Post' object has no attribute 'get_absolute_url'

During handling of the above exception, another exception occurred:

Traceback (most recent call last):
  File "C:\Users\User\AppData\Local\Programs\Python\Python311\Lib\site-packages\django\core\handlers\exception.py", line 55, in inner
    response = get_response(request)
               ^^^^^^^^^^^^^^^^^^^^^
  File "C:\Users\User\AppData\Local\Programs\Python\Python311\Lib\site-packages\django\core\handlers\base.py", line 197, in _get_response
    response = wrapped_callback(request, *callback_args, **callback_kwargs)
               ^^^^^^^^^^^^^^^^^^^^^^^^^^^^^^^^^^^^^^^^^^^^^^^^^^^^^^^^^^^^
  File "C:\Users\User\AppData\Local\Programs\Python\Python311\Lib\site-packages\django\views\generic\base.py", line 104, in view
    return self.dispatch(request, *args, **kwargs)
           ^^^^^^^^^^^^^^^^^^^^^^^^^^^^^^^^^^^^^^^
  File "C:\Users\User\AppData\Local\Programs\Python\Python311\Lib\site-packages\django\contrib\auth\mixins.py", line 73, in dispatch
    return super().dispatch(request, *args, **kwargs)
           ^^^^^^^^^^^^^^^^^^^^^^^^^^^^^^^^^^^^^^^^^^
  File "C:\Users\User\AppData\Local\Programs\Python\Python311\Lib\site-packages\django\contrib\auth\mixins.py", line 109, in dispatch
    return super().dispatch(request, *args, **kwargs)
           ^^^^^^^^^^^^^^^^^^^^^^^^^^^^^^^^^^^^^^^^^^
  File "C:\Users\User\AppData\Local\Programs\Python\Python311\Lib\site-packages\django\views\generic\base.py", line 143, in dispatch
    return handler(request, *args, **kwargs)
           ^^^^^^^^^^^^^^^^^^^^^^^^^^^^^^^^^
  File "C:\Users\User\AppData\Local\Programs\Python\Python311\Lib\site-packages\django\views\generic\edit.py", line 208, in post
    return super().post(request, *args, **kwargs)
           ^^^^^^^^^^^^^^^^^^^^^^^^^^^^^^^^^^^^^^
  File "C:\Users\User\AppData\Local\Programs\Python\Python311\Lib\site-packages\django\views\generic\edit.py", line 153, in post
    return self.form_valid(form)
           ^^^^^^^^^^^^^^^^^^^^^
  File "C:\Users\User\AppData\Local\Programs\Python\Python311\Lib\site-packages\django\views\generic\edit.py", line 136, in form_valid
    return super().form_valid(form)
           ^^^^^^^^^^^^^^^^^^^^^^^^
  File "C:\Users\User\AppData\Local\Programs\Python\Python311\Lib\site-packages\django\views\generic\edit.py", line 65, in form_valid
    return HttpResponseRedirect(self.get_success_url())
                                ^^^^^^^^^^^^^^^^^^^^^^
  File "C:\Users\User\AppData\Local\Programs\Python\Python311\Lib\site-packages\django\views\generic\edit.py", line 127, in get_success_url
    raise ImproperlyConfigured(
django.core.exceptions.ImproperlyConfigured: No URL to redirect to.  Either provide a url or define a get_absolute_url method on the Model.
[2023-10-04 19:42:45,475] ERROR "POST /news/11/edit/ HTTP/1.1" 500 113353 C:\Users\User\AppData\Local\Programs\Python\Python311\Lib\site-packages\django\core\servers\basehttp.py
None
[2023-10-04 19:44:03,895] ERROR Internal Server Error: /news/10/edit/ C:\Users\User\AppData\Local\Programs\Python\Python311\Lib\site-packages\django\utils\log.py
(<class 'django.core.exceptions.ImproperlyConfigured'>, ImproperlyConfigured('No URL to redirect to.  Either provide a url or define a get_absolute_url method on the Model.'), <traceback object at 0x000001B880B8A3C0>)
Traceback (most recent call last):
  File "C:\Users\User\AppData\Local\Programs\Python\Python311\Lib\site-packages\django\views\generic\edit.py", line 125, in get_success_url
    url = self.object.get_absolute_url()
          ^^^^^^^^^^^^^^^^^^^^^^^^^^^^
AttributeError: 'Post' object has no attribute 'get_absolute_url'

During handling of the above exception, another exception occurred:

Traceback (most recent call last):
  File "C:\Users\User\AppData\Local\Programs\Python\Python311\Lib\site-packages\django\core\handlers\exception.py", line 55, in inner
    response = get_response(request)
               ^^^^^^^^^^^^^^^^^^^^^
  File "C:\Users\User\AppData\Local\Programs\Python\Python311\Lib\site-packages\django\core\handlers\base.py", line 197, in _get_response
    response = wrapped_callback(request, *callback_args, **callback_kwargs)
               ^^^^^^^^^^^^^^^^^^^^^^^^^^^^^^^^^^^^^^^^^^^^^^^^^^^^^^^^^^^^
  File "C:\Users\User\AppData\Local\Programs\Python\Python311\Lib\site-packages\django\views\generic\base.py", line 104, in view
    return self.dispatch(request, *args, **kwargs)
           ^^^^^^^^^^^^^^^^^^^^^^^^^^^^^^^^^^^^^^^
  File "C:\Users\User\AppData\Local\Programs\Python\Python311\Lib\site-packages\django\contrib\auth\mixins.py", line 73, in dispatch
    return super().dispatch(request, *args, **kwargs)
           ^^^^^^^^^^^^^^^^^^^^^^^^^^^^^^^^^^^^^^^^^^
  File "C:\Users\User\AppData\Local\Programs\Python\Python311\Lib\site-packages\django\contrib\auth\mixins.py", line 109, in dispatch
    return super().dispatch(request, *args, **kwargs)
           ^^^^^^^^^^^^^^^^^^^^^^^^^^^^^^^^^^^^^^^^^^
  File "C:\Users\User\AppData\Local\Programs\Python\Python311\Lib\site-packages\django\views\generic\base.py", line 143, in dispatch
    return handler(request, *args, **kwargs)
           ^^^^^^^^^^^^^^^^^^^^^^^^^^^^^^^^^
  File "C:\Users\User\AppData\Local\Programs\Python\Python311\Lib\site-packages\django\views\generic\edit.py", line 208, in post
    return super().post(request, *args, **kwargs)
           ^^^^^^^^^^^^^^^^^^^^^^^^^^^^^^^^^^^^^^
  File "C:\Users\User\AppData\Local\Programs\Python\Python311\Lib\site-packages\django\views\generic\edit.py", line 153, in post
    return self.form_valid(form)
           ^^^^^^^^^^^^^^^^^^^^^
  File "C:\Users\User\AppData\Local\Programs\Python\Python311\Lib\site-packages\django\views\generic\edit.py", line 136, in form_valid
    return super().form_valid(form)
           ^^^^^^^^^^^^^^^^^^^^^^^^
  File "C:\Users\User\AppData\Local\Programs\Python\Python311\Lib\site-packages\django\views\generic\edit.py", line 65, in form_valid
    return HttpResponseRedirect(self.get_success_url())
                                ^^^^^^^^^^^^^^^^^^^^^^
  File "C:\Users\User\AppData\Local\Programs\Python\Python311\Lib\site-packages\django\views\generic\edit.py", line 127, in get_success_url
    raise ImproperlyConfigured(
django.core.exceptions.ImproperlyConfigured: No URL to redirect to.  Either provide a url or define a get_absolute_url method on the Model.
[2023-10-04 19:44:03,926] ERROR "POST /news/10/edit/ HTTP/1.1" 500 113371 C:\Users\User\AppData\Local\Programs\Python\Python311\Lib\site-packages\django\core\servers\basehttp.py
None
[2023-10-04 19:44:41,591] ERROR Internal Server Error: /news/9/edit/ C:\Users\User\AppData\Local\Programs\Python\Python311\Lib\site-packages\django\utils\log.py
(<class 'django.core.exceptions.ImproperlyConfigured'>, ImproperlyConfigured('No URL to redirect to.  Either provide a url or define a get_absolute_url method on the Model.'), <traceback object at 0x000001B880B8BA80>)
Traceback (most recent call last):
  File "C:\Users\User\AppData\Local\Programs\Python\Python311\Lib\site-packages\django\views\generic\edit.py", line 125, in get_success_url
    url = self.object.get_absolute_url()
          ^^^^^^^^^^^^^^^^^^^^^^^^^^^^
AttributeError: 'Post' object has no attribute 'get_absolute_url'

During handling of the above exception, another exception occurred:

Traceback (most recent call last):
  File "C:\Users\User\AppData\Local\Programs\Python\Python311\Lib\site-packages\django\core\handlers\exception.py", line 55, in inner
    response = get_response(request)
               ^^^^^^^^^^^^^^^^^^^^^
  File "C:\Users\User\AppData\Local\Programs\Python\Python311\Lib\site-packages\django\core\handlers\base.py", line 197, in _get_response
    response = wrapped_callback(request, *callback_args, **callback_kwargs)
               ^^^^^^^^^^^^^^^^^^^^^^^^^^^^^^^^^^^^^^^^^^^^^^^^^^^^^^^^^^^^
  File "C:\Users\User\AppData\Local\Programs\Python\Python311\Lib\site-packages\django\views\generic\base.py", line 104, in view
    return self.dispatch(request, *args, **kwargs)
           ^^^^^^^^^^^^^^^^^^^^^^^^^^^^^^^^^^^^^^^
  File "C:\Users\User\AppData\Local\Programs\Python\Python311\Lib\site-packages\django\contrib\auth\mixins.py", line 73, in dispatch
    return super().dispatch(request, *args, **kwargs)
           ^^^^^^^^^^^^^^^^^^^^^^^^^^^^^^^^^^^^^^^^^^
  File "C:\Users\User\AppData\Local\Programs\Python\Python311\Lib\site-packages\django\contrib\auth\mixins.py", line 109, in dispatch
    return super().dispatch(request, *args, **kwargs)
           ^^^^^^^^^^^^^^^^^^^^^^^^^^^^^^^^^^^^^^^^^^
  File "C:\Users\User\AppData\Local\Programs\Python\Python311\Lib\site-packages\django\views\generic\base.py", line 143, in dispatch
    return handler(request, *args, **kwargs)
           ^^^^^^^^^^^^^^^^^^^^^^^^^^^^^^^^^
  File "C:\Users\User\AppData\Local\Programs\Python\Python311\Lib\site-packages\django\views\generic\edit.py", line 208, in post
    return super().post(request, *args, **kwargs)
           ^^^^^^^^^^^^^^^^^^^^^^^^^^^^^^^^^^^^^^
  File "C:\Users\User\AppData\Local\Programs\Python\Python311\Lib\site-packages\django\views\generic\edit.py", line 153, in post
    return self.form_valid(form)
           ^^^^^^^^^^^^^^^^^^^^^
  File "C:\Users\User\AppData\Local\Programs\Python\Python311\Lib\site-packages\django\views\generic\edit.py", line 136, in form_valid
    return super().form_valid(form)
           ^^^^^^^^^^^^^^^^^^^^^^^^
  File "C:\Users\User\AppData\Local\Programs\Python\Python311\Lib\site-packages\django\views\generic\edit.py", line 65, in form_valid
    return HttpResponseRedirect(self.get_success_url())
                                ^^^^^^^^^^^^^^^^^^^^^^
  File "C:\Users\User\AppData\Local\Programs\Python\Python311\Lib\site-packages\django\views\generic\edit.py", line 127, in get_success_url
    raise ImproperlyConfigured(
django.core.exceptions.ImproperlyConfigured: No URL to redirect to.  Either provide a url or define a get_absolute_url method on the Model.
[2023-10-04 19:44:41,653] ERROR "POST /news/9/edit/ HTTP/1.1" 500 113342 C:\Users\User\AppData\Local\Programs\Python\Python311\Lib\site-packages\django\core\servers\basehttp.py
None
[2023-10-04 19:45:02,427] ERROR Internal Server Error: /news/8/edit/ C:\Users\User\AppData\Local\Programs\Python\Python311\Lib\site-packages\django\utils\log.py
(<class 'django.core.exceptions.ImproperlyConfigured'>, ImproperlyConfigured('No URL to redirect to.  Either provide a url or define a get_absolute_url method on the Model.'), <traceback object at 0x000001B880B2C100>)
Traceback (most recent call last):
  File "C:\Users\User\AppData\Local\Programs\Python\Python311\Lib\site-packages\django\views\generic\edit.py", line 125, in get_success_url
    url = self.object.get_absolute_url()
          ^^^^^^^^^^^^^^^^^^^^^^^^^^^^
AttributeError: 'Post' object has no attribute 'get_absolute_url'

During handling of the above exception, another exception occurred:

Traceback (most recent call last):
  File "C:\Users\User\AppData\Local\Programs\Python\Python311\Lib\site-packages\django\core\handlers\exception.py", line 55, in inner
    response = get_response(request)
               ^^^^^^^^^^^^^^^^^^^^^
  File "C:\Users\User\AppData\Local\Programs\Python\Python311\Lib\site-packages\django\core\handlers\base.py", line 197, in _get_response
    response = wrapped_callback(request, *callback_args, **callback_kwargs)
               ^^^^^^^^^^^^^^^^^^^^^^^^^^^^^^^^^^^^^^^^^^^^^^^^^^^^^^^^^^^^
  File "C:\Users\User\AppData\Local\Programs\Python\Python311\Lib\site-packages\django\views\generic\base.py", line 104, in view
    return self.dispatch(request, *args, **kwargs)
           ^^^^^^^^^^^^^^^^^^^^^^^^^^^^^^^^^^^^^^^
  File "C:\Users\User\AppData\Local\Programs\Python\Python311\Lib\site-packages\django\contrib\auth\mixins.py", line 73, in dispatch
    return super().dispatch(request, *args, **kwargs)
           ^^^^^^^^^^^^^^^^^^^^^^^^^^^^^^^^^^^^^^^^^^
  File "C:\Users\User\AppData\Local\Programs\Python\Python311\Lib\site-packages\django\contrib\auth\mixins.py", line 109, in dispatch
    return super().dispatch(request, *args, **kwargs)
           ^^^^^^^^^^^^^^^^^^^^^^^^^^^^^^^^^^^^^^^^^^
  File "C:\Users\User\AppData\Local\Programs\Python\Python311\Lib\site-packages\django\views\generic\base.py", line 143, in dispatch
    return handler(request, *args, **kwargs)
           ^^^^^^^^^^^^^^^^^^^^^^^^^^^^^^^^^
  File "C:\Users\User\AppData\Local\Programs\Python\Python311\Lib\site-packages\django\views\generic\edit.py", line 208, in post
    return super().post(request, *args, **kwargs)
           ^^^^^^^^^^^^^^^^^^^^^^^^^^^^^^^^^^^^^^
  File "C:\Users\User\AppData\Local\Programs\Python\Python311\Lib\site-packages\django\views\generic\edit.py", line 153, in post
    return self.form_valid(form)
           ^^^^^^^^^^^^^^^^^^^^^
  File "C:\Users\User\AppData\Local\Programs\Python\Python311\Lib\site-packages\django\views\generic\edit.py", line 136, in form_valid
    return super().form_valid(form)
           ^^^^^^^^^^^^^^^^^^^^^^^^
  File "C:\Users\User\AppData\Local\Programs\Python\Python311\Lib\site-packages\django\views\generic\edit.py", line 65, in form_valid
    return HttpResponseRedirect(self.get_success_url())
                                ^^^^^^^^^^^^^^^^^^^^^^
  File "C:\Users\User\AppData\Local\Programs\Python\Python311\Lib\site-packages\django\views\generic\edit.py", line 127, in get_success_url
    raise ImproperlyConfigured(
django.core.exceptions.ImproperlyConfigured: No URL to redirect to.  Either provide a url or define a get_absolute_url method on the Model.
[2023-10-04 19:45:02,574] ERROR "POST /news/8/edit/ HTTP/1.1" 500 113563 C:\Users\User\AppData\Local\Programs\Python\Python311\Lib\site-packages\django\core\servers\basehttp.py
None
[2023-10-04 19:45:45,204] ERROR Internal Server Error: /news/7/edit/ C:\Users\User\AppData\Local\Programs\Python\Python311\Lib\site-packages\django\utils\log.py
(<class 'django.core.exceptions.ImproperlyConfigured'>, ImproperlyConfigured('No URL to redirect to.  Either provide a url or define a get_absolute_url method on the Model.'), <traceback object at 0x000001B880BBDFC0>)
Traceback (most recent call last):
  File "C:\Users\User\AppData\Local\Programs\Python\Python311\Lib\site-packages\django\views\generic\edit.py", line 125, in get_success_url
    url = self.object.get_absolute_url()
          ^^^^^^^^^^^^^^^^^^^^^^^^^^^^
AttributeError: 'Post' object has no attribute 'get_absolute_url'

During handling of the above exception, another exception occurred:

Traceback (most recent call last):
  File "C:\Users\User\AppData\Local\Programs\Python\Python311\Lib\site-packages\django\core\handlers\exception.py", line 55, in inner
    response = get_response(request)
               ^^^^^^^^^^^^^^^^^^^^^
  File "C:\Users\User\AppData\Local\Programs\Python\Python311\Lib\site-packages\django\core\handlers\base.py", line 197, in _get_response
    response = wrapped_callback(request, *callback_args, **callback_kwargs)
               ^^^^^^^^^^^^^^^^^^^^^^^^^^^^^^^^^^^^^^^^^^^^^^^^^^^^^^^^^^^^
  File "C:\Users\User\AppData\Local\Programs\Python\Python311\Lib\site-packages\django\views\generic\base.py", line 104, in view
    return self.dispatch(request, *args, **kwargs)
           ^^^^^^^^^^^^^^^^^^^^^^^^^^^^^^^^^^^^^^^
  File "C:\Users\User\AppData\Local\Programs\Python\Python311\Lib\site-packages\django\contrib\auth\mixins.py", line 73, in dispatch
    return super().dispatch(request, *args, **kwargs)
           ^^^^^^^^^^^^^^^^^^^^^^^^^^^^^^^^^^^^^^^^^^
  File "C:\Users\User\AppData\Local\Programs\Python\Python311\Lib\site-packages\django\contrib\auth\mixins.py", line 109, in dispatch
    return super().dispatch(request, *args, **kwargs)
           ^^^^^^^^^^^^^^^^^^^^^^^^^^^^^^^^^^^^^^^^^^
  File "C:\Users\User\AppData\Local\Programs\Python\Python311\Lib\site-packages\django\views\generic\base.py", line 143, in dispatch
    return handler(request, *args, **kwargs)
           ^^^^^^^^^^^^^^^^^^^^^^^^^^^^^^^^^
  File "C:\Users\User\AppData\Local\Programs\Python\Python311\Lib\site-packages\django\views\generic\edit.py", line 208, in post
    return super().post(request, *args, **kwargs)
           ^^^^^^^^^^^^^^^^^^^^^^^^^^^^^^^^^^^^^^
  File "C:\Users\User\AppData\Local\Programs\Python\Python311\Lib\site-packages\django\views\generic\edit.py", line 153, in post
    return self.form_valid(form)
           ^^^^^^^^^^^^^^^^^^^^^
  File "C:\Users\User\AppData\Local\Programs\Python\Python311\Lib\site-packages\django\views\generic\edit.py", line 136, in form_valid
    return super().form_valid(form)
           ^^^^^^^^^^^^^^^^^^^^^^^^
  File "C:\Users\User\AppData\Local\Programs\Python\Python311\Lib\site-packages\django\views\generic\edit.py", line 65, in form_valid
    return HttpResponseRedirect(self.get_success_url())
                                ^^^^^^^^^^^^^^^^^^^^^^
  File "C:\Users\User\AppData\Local\Programs\Python\Python311\Lib\site-packages\django\views\generic\edit.py", line 127, in get_success_url
    raise ImproperlyConfigured(
django.core.exceptions.ImproperlyConfigured: No URL to redirect to.  Either provide a url or define a get_absolute_url method on the Model.
[2023-10-04 19:45:45,237] ERROR "POST /news/7/edit/ HTTP/1.1" 500 113336 C:\Users\User\AppData\Local\Programs\Python\Python311\Lib\site-packages\django\core\servers\basehttp.py
None
